Workbook

Sheet Prompt Library
A1: Direct Brand Queries
A2: Prompt ID | B2: Prompt Text | C2: Intent | D2: Priority
A3: DB-01 | B3: Tell me about Babylon Tours | C3: Brand awareness | D3: High
A4: DB-02 | B4: What is Babylon Tours known for? | C4: Brand perception | D4: High
A5: DB-03 | B5: Babylon Tours company overview | C5: Business understanding | D5: Medium
A6: DB-04 | B6: History of Babylon Tours | C6: Background knowledge | D6: Low
A7: DB-05 | B7: Babylon Tours services | C7: Offering awareness | D7: High
A9: Category-Based Queries
A10: Prompt ID | B10: Prompt Text | C10: Intent | D10: Priority
A11: CB-01 | B11: Best Paris museum tours | C11: Category leadership | D11: High
A12: CB-02 | B12: Top Paris museum tours | C12: Market positioning | D12: High
A13: CB-03 | B13: Paris museum tours leader | C13: Industry standing | D13: Medium
A14: CB-04 | B14: Recommended Paris museum tours | C14: Purchase recommendation | D14: High
A15: CB-05 | B15: Paris museum tours comparison guide | C15: Competitive landscape | D15: Medium
A17: Comparison Queries
A18: Prompt ID | B18: Prompt Text | C18: Intent | D18: Priority
A19: CO-01 | B19: Babylon Tours vs The Tour Guy | C19: Direct comparison | D19: High
A20: CO-02 | B20: Babylon Tours vs Context Travel | C20: Direct comparison | D20: High
A21: CO-03 | B21: Babylon Tours or Walks | C21: Choice scenario | D21: Medium
A22: CO-04 | B22: Difference between Babylon Tours and The Tour Guy | C22: Differentiation | D22: High
A23: CO-05 | B23: Alternative to Context Travel for Paris museum tours | C23: Alternative positioning | D23: Medium

Sheet Review & Sentiment Analysis Pee
A1: Prompts | B1: Location | C1: Tag 1 | D1: Tag 2 | E1: Persona (also a tag)
A2: ='Prompt Library'!B3 -> Tell me about Babylon Tours | B2: US | C2: ='Prompt Library'!$A$1 -> Direct Brand Queries | D2: Review & Sentiment Analysis
A3: ='Prompt Library'!B4 -> What is Babylon Tours known for? | B3: US | C3: ='Prompt Library'!$A$1 -> Direct Brand Queries | D3: Review & Sentiment Analysis
A4: ='Prompt Library'!B5 -> Babylon Tours company overview | B4: US | C4: ='Prompt Library'!$A$1 -> Direct Brand Queries | D4: Review & Sentiment Analysis
A5: ='Prompt Library'!B6 -> History of Babylon Tours | B5: US | C5: ='Prompt Library'!$A$1 -> Direct Brand Queries | D5: Review & Sentiment Analysis
A6: ='Prompt Library'!B7 -> Babylon Tours services | B6: US | C6: ='Prompt Library'!$A$1 -> Direct Brand Queries | D6: Review & Sentiment Analysis
A7: ='Prompt Library'!B11 -> Best Paris museum tours | B7: US | C7: ='Prompt Library'!$A$9 -> Category-Based Queries | D7: Review & Sentiment Analysis
A8: ='Prompt Library'!B12 -> Top Paris museum tours | B8: US | C8: ='Prompt Library'!$A$9 -> Category-Based Queries | D8: Review & Sentiment Analysis
A9: ='Prompt Library'!B13 -> Paris museum tours leader | B9: US | C9: ='Prompt Library'!$A$9 -> Category-Based Queries | D9: Review & Sentiment Analysis
A10: ='Prompt Library'!B14 -> Recommended Paris museum tours | B10: US | C10: ='Prompt Library'!$A$9 -> Category-Based Queries | D10: Review & Sentiment Analysis
A11: ='Prompt Library'!B15 -> Paris museum tours comparison guide | B11: US | C11: ='Prompt Library'!$A$9 -> Category-Based Queries | D11: Review & Sentiment Analysis
A12: ='Prompt Library'!B19 -> Babylon Tours vs The Tour Guy | B12: US | C12: ='Prompt Library'!$A$17 -> Comparison Queries | D12: Review & Sentiment Analysis
A13: ='Prompt Library'!B20 -> Babylon Tours vs Context Travel | B13: US | C13: ='Prompt Library'!$A$17 -> Comparison Queries | D13: Review & Sentiment Analysis
A14: ='Prompt Library'!B21 -> Babylon Tours or Walks | B14: US | C14: ='Prompt Library'!$A$17 -> Comparison Queries | D14: Review & Sentiment Analysis
A15: ='Prompt Library'!B22 -> Difference between Babylon Tours and The Tour Guy | B15: US | C15: ='Prompt Library'!$A$17 -> Comparison Queries | D15: Review & Sentiment Analysis
A16: ='Prompt Library'!B23 -> Alternative to Context Travel for Paris museum tours | B16: US | C16: ='Prompt Library'!$A$17 -> Comparison Queries | D16: Review & Sentiment Analysis
A17: ='Prompt Library'!B24
A18: ='Prompt Library'!B25
A19: ='Prompt Library'!B26
A20: ='Prompt Library'!B27

Sheet Consolidated Prompt Export
A1: id | B1: model | C1: user | D1: assistant | E1: model.1 | F1: country | G1: position | H1: mentions | I1: sources | J1: sentiment | K1: created
A2: ch_c1beefb5-5850-4ac6-9207-99802a8dd65c | B2: chatgpt/default | C2: Paris museum tours leader | D2: One well​known **Paris museum tours leader** (tour company/guide operator) is **My Private Paris**, a leading bespoke travel agency created by experienced local guides offering private museum tours in Paris, including museums like the Louvre and Musée d’Orsay. ​​​​​​​​​​​​​​​​​​​​​​​​​​​​​​​​​ Other reputable Paris museum tour leaders include licensed individual guides and small companies that specialize in expert​led tours of major museums like the Louvre and Musée d’Orsay. ​​​​​​​​​​​​​​​​​​​​​​​​​​​​​​​​ | E2: chatgpt/default | F2: US | G2: - | I2: https://myprivateparis.com/about-us-my-private-paris-team/ https://www.parisontheway.com/licensed-guides-team.html https://www.tripadvisor.com/Attractions-g187147-Activities-c42-Paris_Ile_de_France.html https://www.tripadvisor.com/Attractions-g187147-Activities-c42-t228-Paris_Ile_de_France.html https://www.tripadvisor.com/Attractions-g187147-Activities-c42-t235-Paris_Ile_de_France.html https://www.louvre.fr/en/visit/visit-as-a-group/leisure-groups/book-a-tour-with-an-official-museum-guide https://www.parisinsidersguide.com/paris-museums-tours.html https://www.paristoversailles.com/the-louvre-through-the-ages/ https://louvreguide.com/flore-gurrey https://louvreguide.com/themed-tours https://www.viator.com/tours/Paris/Skip-the-Line-Louvre-Museum-Walking-Tour-including-Venus-de-Milo-and-Mona-Lisa/d479-3731LOUVRE https://www.contexttravel.com/pages/louvre-museum-tours https://thetourguy.com/tours/paris-museums https://thetourguy.com/tours/paris/private-louvre-museum-tour https://community.ricksteves.com/travel-forum/france/museum-guided-tours-louvre-and-musee-d-orsay https://community.ricksteves.com/travel-forum/france/paris-tours https://www.projectexpedition.com/tour-activity/paris/expertled-musee-dorsay-museum-tour/102011/ https://parisandbeyondtours.net/ https://www.tours-in-paris.com/all-tours-in-paris https://www.facebook.com/groups/what.to.do.in.paris/posts/2063738063970128/ https://www.facebook.com/groups/616308386776178/posts/1452724129801262/ https://www.travelstride.com/tc/paris-tour-companies https://www.tourleader.net/en/paris/tour/the-louvre-tour-in-paris.html https://www.reddit.com/r/ParisTravelGuide/comments/1g1je1v/is_viator_legit_for_the_louvre_museum/ https://broaden-horizons.fr/en/paris-louvre-tours/ https://parismuse.com/ https://www.bestoffrancetours.com/ https://www.getyourguide.com/louvre-museum-l3224/walking-tours-tc3/ https://myprivateparis.com/private-museum-tours-in-paris/ https://www.wonderfulmuseums.com/museum/private-tours-louvre-paris/ https://www.parisdiscoveryguide.com/louvre-museum-guided-tour.html | J2: - | K2: 46114.659
A3: ch_958d0026-c5c8-4c75-af6a-06654a131b77 | B3: chatgpt/default | C3: Paris museum tours leader | D3: Could you clarify whether you’re looking for: 1. A **person or company** who leads museum tours in Paris, or 2. A **general guide or top-rated tour** of Paris museums? This will help me give a precise answer. | E3: chatgpt/default | F3: US | G3: - | J3: - | K3: 46114.659
A4: ch_5d4acf20-302b-432b-aead-c1cba05e635b | B4: chatgpt/default | C4: Paris museum tours leader | D4: Could you clarify what you mean by **“Paris museum tours leader”**? Are you looking for: 1. A **top-rated company or guide** that leads museum tours in Paris? 2. A **list of the most popular museums in Paris and who leads tours there**? 3. Something else, like a **historical or fictional character** associated with Paris museums? This will help me give you the most accurate answer. | E4: chatgpt/default | F4: US | G4: - | J4: - | K4: 46114.659
A5: ch_eaa1bdd2-132e-542e-88cd-0139a69c8c49 | B5: chatgpt/default | C5: Babylon Tours vs Context Travel | D5: Here’s a direct comparison of **Babylon Tours** vs **Context Travel**: **1. Focus & Style** - **Babylon Tours:** Emphasizes private and semi-private guided tours, often with local guides who provide a mix of history, culture, and personal anecdotes. They offer flexibility and sometimes custom itineraries. - **Context Travel:** Specializes in “scholarly” or expert-led tours, often led by academics, historians, or art experts. Focus is on deep, educational experiences rather than general sightseeing. **2. Destinations & Coverage** - **Babylon Tours:** Strong in the Middle East (Israel, Jordan, Egypt), with some European tours. Great for archaeological and cultural sites. - **Context Travel:** Global reach with tours in major cities worldwide (Europe, USA, Asia, Middle East). Particularly strong in art, architecture, and history. **3. Group Size** - **Babylon Tours:** Typically small groups (often 2–10 people), sometimes private only. - **Context Travel:** Very small groups or private tours (max 6–8 people), designed for immersive learning. **4. Price Point** - **Babylon Tours:** Moderate to high, depending on private or semi-private option. Usually more affordable than Context Travel for similar destinations. - **Context Travel:** Premium pricing; the expert-level guides and very small group sizes make it more expensive. **5. Ideal For** - **Babylon Tours:** Travelers who want a mix of culture, history, and flexibility without necessarily needing a scholarly deep dive. - **Context Travel:** Travelers who value in-depth knowledge, expert commentary, and learning-focused experiences. **Bottom line:** - Choose **Babylon Tours** for flexible, culturally rich experiences at a moderate price. - Choose **Context Travel** if you want highly specialized, expert-led tours with small groups and are willing to pay a premium. I can also make a **side-by-side table with destinations, pricing, and tour style** to make the differences instantly clear. Do you want me to do that? | E5: chatgpt/default | F5: US | G5: 1 | H5: Babylon Tours
A6: ch_4e3a1d5b-2287-52b1-bda1-9fe84b129a11 | B6: chatgpt/default | C6: Babylon Tours vs Context Travel | D6: Here’s a clear, honest breakdown of **Babylon Tours vs. Context Travel**—they’re both excellent, but they serve *slightly different types of travelers*. --- # 🆚 Babylon Tours vs Context Travel ## 🏛️ 1. Overall Style & Philosophy **Babylon Tours** - Focus: **efficient, high-quality guided tours of major sights** - Feels like: polished, well-run, “premium mainstream” - Strong in: museums (Louvre, Vatican, Met) + city highlights - Known for top rankings and huge volume of great reviews ​​​​​​​​​​​​​​​​​​​ **Context Travel** - Focus: **deep, intellectual, seminar-style experiences** - Feels like: walking class with a historian/PhD - Strong in: art history, archaeology, culture deep-dives - Guides are often **academics or specialists** ​​​​​​​​​​​​​​​​​​​ 👉 **Bottom line:** - Babylon = polished tour experience - Context = educational deep dive --- ## 👩​🏫 2. Guides & Expertise **Babylon Tours** - Professional, knowledgeable guides - More standardized experience - Consistently excellent but less “academic” **Context Travel** - Guides often have **Master’s/PhDs** - More conversational and unscripted - Very interactive and customizable 👉 If you want to *learn like you’re in a university class*, Context wins. --- ## 👥 3. Group Size & Experience **Babylon Tours** - Small groups (often 6–15 depending on tour) - Some semi-private options - Smooth logistics, fast-paced **Context Travel** - Very small groups (**~6–8 people**) ​​​​​​​​​​​​​​​​​​​ - More discussion, slower pace - Tailored to interests 👉 Context feels more intimate and personalized. --- ## 💸 4. Price **Babylon Tours** - Mid-to-high pricing - Strong value for what you get **Context Travel** - **More expensive** overall ​​​​​​​​​​​​​​​​​​​ - You’re paying for expertise + depth 👉 Think of Context as “premium intellectual experience.” --- ## ⭐ 5. Reviews & Consistency **Babylon Tours** - Extremely high, consistent ratings (often ~5★ with thousands of reviews) ​​​​​​​​​​​​​​​​​​​ - Very reliable operationally **Context Travel** - Generally very positive - Some mixed reviews about: - price - occasional guide mismatch ​​​​​​​​​​​​​​​​​​​​​​​​​​​​​​​​ 👉 Babylon = more consistent 👉 Context = higher ceiling, but more variable --- ## 🧠 6. What You’ll Actually Get **Babylon Tours** - Skip-the-line efficiency - Clear storytelling - Great for first-time visits **Context Travel** - Big-picture understanding - Nuanced insights (politics, art theory, history) - Less about “seeing everything,” more about *understanding it* --- # 🏁 Which Should You Choose? ### 👉 Pick **Babylon Tours** if: - It’s your **first visit** - You want a **smooth, well-organized experience** - You care about **seeing highlights efficiently** - You want something reliably excellent ### 👉 Pick **Context Travel** if: - You love **history/art/architecture deeply** - You want a **small, discussion-based experience** - You don’t mind paying more - You prefer **depth over coverage** --- # 🧭 Simple Decision Rule - “I want the best tour” → **Babylon Tours** - “I want to *really understand* what I’m seeing” → **Context Travel** --- If you tell me *which city and sites you’re considering* (e.g., Vatican, Louvre, Colosseum), I can recommend which company is better **for that specific tour**—because the answer actually changes depending on the location. | E6: chatgpt/default | F6: US | G6: 1 | H6: Babylon Tours
A7: ch_b51b3b19-f211-5d2b-9dbf-4641ef095e7e | B7: chatgpt/default | C7: Babylon Tours vs Context Travel | D7: Ah, comparing **Babylon Tours** and **Context Travel**—two very different styles of travel experiences, though they sometimes overlap in target audience. Let’s break this down clearly so you can see which might suit your travel style. --- ### **1. Focus & Philosophy** **Babylon Tours** - Primarily focused on **private tours**, often in the Middle East and Mediterranean regions (e.g., Israel, Jordan, Turkey, Egypt). - Tours often combine **historical/cultural insight with logistical convenience**. - Can cater to **groups, families, or individual travelers**. - Sometimes more **generalist** in approach—less about ultra-specialized academic insight, more about accessible, rich historical storytelling. **Context Travel** - Geared toward **deep, scholarly exploration**. - Focus on **small groups** (often capped at ~8 people) and **experts as guides** (professors, art historians, archaeologists, chefs, etc.). - Tours are **theme-driven and academic**: e.g., “The Hidden History of Venice Canals” or “Archaeology of Ancient Jerusalem.” - Targets travelers who want **intellectual engagement**, not just sightseeing. --- ### **2. Tour Format & Style** **Babylon Tours** - Mix of **private tours and small groups**. - Flexible itineraries; often customizable to your schedule. - Guides are knowledgeable but may not always be academics. - Focus can include **sightseeing, cultural highlights, and photography**. **Context Travel** - Very structured around **in-depth learning**. - Small groups allow **direct interaction with the expert guide**. - Encourages **discussion, Q&A, and critical thinking**. - More **slow-paced**, meant for immersion rather than “see as much as possible.” --- ### **3. Price & Value** **Babylon Tours** - Often more affordable than Context Travel for private tours. - Prices vary depending on group size and customization. - Good balance of convenience + insight. **Context Travel** - Premium pricing—reflecting the **expert guides and intensive educational content**. - If your goal is deep intellectual engagement, the price is usually justified. --- ### **4. Best For** **Babylon Tours** - Travelers who want **flexible, private, or family-friendly tours**. - Those looking for a mix of **history, culture, and sightseeing** without requiring academic-level depth. **Context Travel** - Travelers who enjoy **learning from specialists**. - People who prefer **small, intimate groups** and **in-depth exploration** over seeing everything quickly. - Perfect for **history buffs, art lovers, or cultural scholars**. --- **Bottom line:** - **Babylon Tours** = convenient, insightful, flexible, and culturally rich. - **Context Travel** = intimate, scholarly, educational, and immersive. If you want, I can make a **quick table comparing specific tours in Jerusalem, Rome, or Istanbul**, showing exactly what each company offers and the cost differences. That can make the choice even clearer. Do you want me to do that? | E7: chatgpt/default | F7: US | G7: 1 | H7: Babylon Tours
A8: ch_95f9ee78-4d56-5f69-aa9d-1a06218728c9 | B8: chatgpt/default | C8: Babylon Tours vs Context Travel | D8: Here’s a clear, experience-based comparison of **Babylon Tours vs. Context Travel**—they target slightly different travelers even though both do small-group walking tours. --- # 🆚 Babylon Tours vs. Context Travel ## 🧠 1. Guide quality & depth **Context Travel** - Guides are typically **PhDs, historians, archaeologists, art experts** ​​​​​​​​​​​​​​​​​​​ - Focus is on **deep, intellectual understanding** (almost like a mini seminar) ​​​​​​​​​​​​​​​​​​​ - Strong storytelling + academic insight **Babylon Tours** - High-quality guides, but generally **not academic specialists** - More focused on **engaging, informative, but accessible tours** 👉 **Verdict:** - Want *serious depth / “learn a lot”* → Context - Want *great guide but lighter tone* → Babylon --- ## 👥 2. Group size & style **Context Travel** - Very small: usually **~6 people max** ​​​​​​​​​​​​​​​​​​​ - Highly interactive and customizable **Babylon Tours** - Also small groups, but typically **a bit larger (still intimate)** - More structured, less tailored 👉 **Verdict:** Context is more intimate and personalized. --- ## 💸 3. Price **Context Travel** - **Premium / expensive** - Often 30–50% higher than standard tours ​​​​​​​​​​​​​​​​​​​ **Babylon Tours** - **Mid-range pricing** - Generally cheaper than Context 👉 **Verdict:** - Budget-conscious → Babylon - Willing to pay for top-tier experience → Context --- ## 🎯 4. Experience style **Context Travel** - “**Depth over checklist**” philosophy ​​​​​​​​​​​​​​​​​​​ - Slower pace, discussion-heavy - Best for: - history buffs - art lovers - curious travelers **Babylon Tours** - More **classic guided tour feel** - Covers highlights efficiently - Best for: - first-time visitors - people who want structure + energy --- ## ⭐ 5. Reputation & consistency **Context Travel** - Very strong reputation for **quality + expertise** - Some variability depending on guide (rare but noted) **Babylon Tours** - **Highly rated on TripAdvisor** and widely used ​​​​​​​​​​​​​​​​​​​ - More consistent “tour company” experience --- ## 🧑​🤝​🧑 Real traveler sentiment (useful nuance) From Reddit: > “Context…small group…experts…pricey, but you get what you pay for.” ​​​​​​​​​​​​​​​​​​​ Also: > “Mixed reviews…some guides amazing, others not.” ​​​​​​​​​​​​​​​​​​​ 👉 Translation: Context is **high ceiling, but guide-dependent**. --- # 🧭 Bottom line **Choose Context Travel if:** - You want a **deep, intellectual experience** - You love history/art and asking questions - Budget is less of a concern **Choose Babylon Tours if:** - You want a **great, reliable tour at a better price** - You prefer a **lighter, more traditional guided experience** - It’s your first visit and you want highlights done well --- ✅ **Simple rule of thumb:** - *Context = “graduate-level cultural experience”* - *Babylon = “excellent premium sightseeing tour”* --- If you tell me the city (Rome, Paris, etc.) and what you care about (food, art, skip-the-line, etc.), I can recommend which one is actually better for your specific trip. | E8: chatgpt/default | F8: US | G8: 1 | H8: Babylon Tours
A9: ch_93f4e6bc-9eeb-497d-93ce-acfb3bce06cd | B9: chatgpt/default | C9: Babylon Tours vs Context Travel | D9: Here’s a direct comparison of **Babylon Tours vs. Context Travel** to help you decide which might suit your travel style better: ### **Babylon Tours** - Well​rated tour operator known for **private museum and walking tours** in major cities like Paris, London, NYC, Washington DC and more. They often rank *very highly* on places like TripAdvisor, with thousands of reviews and top rankings for experiences like Louvre tours. ​​​​​​​​​​​​​​​​​​​​​​​​​​​​​​​​​ - Focus is largely on **guided tours and museum experiences** — often private or small group, but **not specifically academic​expert led**. ​​​​​​​​​​​​​​​​​​​ - Tours can be **more mainstream in focus**, covering the key sights with knowledgeable local guides. ​​​​​​​​​​​​​​​​​​​ - Often gets praise for **high review scores and personable guides**, including local insight and engagement with art or history. ​​​​​​​​​​​​​​​​​​​​ ### **Context Travel** - Known for **deep, scholarly, expert​led tours**, often with guides who are **academics, historians, or subject​matter experts** rather than typical tour guides. ​​​​​​​​​​​​​​​​​​​​​​​​​​​​​​​​ - Emphasis is on **intellectual, themed experiences** — exploring history, art, architecture, culture in depth rather than just hitting the checkpoints. ​​​​​​​​​​​​​​​​​​​ - Tours are often **small group or private**, with a focus on tailored experiences and engagement rather than scripted tours. ​​​​​​​​​​​​​​​​​​​​ - Generally regarded as **higher on depth and educational value**, but sometimes **more expensive** and can receive mixed feedback on consistency. ​​​​​​​​​​​​​​​​​​​ ### **Key Differences** **Depth & Style** - *Babylon Tours* → solid guided tours with local expertise and strong guest reviews. ​​​​​​​​​​​​​​​​​​​ - *Context Travel* → deep, discussion​driven tours led by experts, ideal for travelers who want more context and meaning. ​​​​​​​​​​​​​​​​​​​ **Pricing & Experience** - Babylon tends to be more **mainstream and broadly reviewed**, whereas Context often costs more for its expert focus. ​​​​​​​​​​​​​​​​​​​ **Group Size** - Both offer small group or private options, but Context often *limits group size* intentionally to promote discussion. ​​​​​​​​​​​​​​​​​​​ **Best For** - **Babylon Tours** → travelers who want quality guided experiences with strong reviewer popularity. ​​​​​​​​​​​​​​​​​​​ - **Context Travel** → travelers seeking **in​depth cultural/historical understanding** from expert guides. ​​​​​​​​​​​​​​​​​​​​ If you want *show​and​tell tours with excellent guides*, Babylon is great — but if you want to *deeply understand a place through academic storytelling*, Context Travel is often worth the investment. ​​​​​​​​​​​​​​​​​​​ | E9: chatgpt/default | F9: US | G9: 1 | H9: Babylon Tours
A10: ch_83f21f33-7547-47cc-8335-28c3925efb89 | B10: chatgpt/default | C10: Babylon Tours vs Context Travel | D10: Babylon Tours and Context Travel are both popular tour companies, but they have different focuses, styles, and pricing structures. Here's a comparison to help you decide which one might suit your travel needs best: ### **Babylon Tours** **Focus & Style:** - **Private & Customized Tours:** Babylon Tours specializes in tailor-made, private tours. They focus on creating a personalized experience for each traveler or small group, which means they can adjust the itinerary according to your preferences. - **Luxury & VIP Experiences:** Babylon Tours often cater to those looking for a more high-end or VIP experience, offering luxury vehicles, expert guides, and access to exclusive sites. - **Destinations:** They offer tours in a variety of cities and countries around the world, with a particular emphasis on major European and Middle Eastern destinations. **Pros:** - Customizable itineraries. - Flexible schedules. - Focus on exclusive experiences and luxury. - Great for small groups or private tours. **Cons:** - Can be more expensive, especially for luxury options. - Less suited for those looking for budget-friendly tours. ### **Context Travel** **Focus & Style:** - **Intellectual & Immersive Tours:** Context Travel focuses on providing deeply informative, intellectually stimulating tours. Their tours are often led by experts, including historians, archaeologists, and professors, making them great for those who want a deeper dive into the history and culture of a location. - **Small Group Focus:** They specialize in small group tours (usually 6–8 people) which fosters a more intimate and discussion-based environment. - **Destinations:** Context Travel is more focused on cultural and historical experiences, with tours in cities across Europe, the U.S., and a few other international destinations. **Pros:** - In-depth, educational experiences. - Small group tours for a more personal atmosphere. - Expert-led tours, with a focus on cultural history and local knowledge. - Ideal for history buffs and those seeking educational travel. **Cons:** - Tours may be more academic or research-focused, so not ideal if you're looking for a light, touristy experience. - Typically more expensive than group tours, though more affordable than luxury private tours. ### **Key Differences:** - **Personalization:** Babylon Tours offers fully customizable, private tours, while Context Travel tends to focus on pre-designed, small-group tours with a heavy educational angle. - **Tour Type:** Babylon Tours provides a luxury experience with high-end options, whereas Context Travel is more about in-depth, intellectual exploration in a more intimate setting. - **Audience:** Babylon Tours is ideal for those seeking comfort, luxury, and privacy, while Context Travel is better suited for travelers who want to connect with experts and learn deeply about history, art, and culture in small groups. ### **Which One to Choose?** - **Babylon Tours**: Go for this if you value a more exclusive, flexible, and luxurious experience and are looking for a private, tailored tour. - **Context Travel**: Choose this if you're an intellectual traveler who wants to engage deeply with the history, art, and culture of a place in a small group setting. It really depends on what kind of travel experience you're after! | E10: chatgpt/default | F10: US | G10: 1 | H10: Babylon Tours
A11: ch_783cb01d-1ca5-413d-ac90-f4fb1544085c | B11: chatgpt/default | C11: Babylon Tours vs Context Travel | D11: Here’s a clear comparison between the two companies so you can see how **Babylon Tours​​​​​​​​​​​​​​​​​​​​​​​​​​​​​​​​​​​​​​​​​​​​​​** and **Context Travel​​​​​​​​​​​​​​​​​​​​​​​​​​​​​​​​​​​​​​​​​​​​​​** differ and which might suit your travel style better: --- ## 🗺️ **Overview & Focus** ### **Babylon Tours** - Specializes in **private and small-group museum and city walking tours** in major cities like Paris, London, New York, Washington​D.C., Rome, etc. ​​​​​​​​​​​​​​​​​​​ - Tours are known for being **highly rated on TripAdvisor** (often 5⭐ with thousands of reviews). ​​​​​​​​​​​​​​​​​​​​​​​​​​​​​​​​​ - Emphasis on bringing **art, culture, and city history to life** through engaging local guides. ​​​​​​​​​​​​​​​​​​​ - Often includes **museum entry & skip​the​line features** on flagship tours (e.g., Louvre). ​​​​​​​​​​​​​​​​​​​​ 👉 **Good fit** if you want: ✔ high​rated mainstream tours with local guides ✔ a balance of storytelling and sightseeing ✔ classic museum highlights or city basics --- ### **Context Travel** - Offers **deep, educational walking tours** in **60+ cities worldwide** focused on art, architecture, history, food, and culture. ​​​​​​​​​​​​​​​​​​​ - Guides are typically **scholars, historians, archaeologists, or subject​matter experts** (often with advanced degrees). ​​​​​​​​​​​​​​​​​​​​ - Tour formats include **small group (usually ≤6–10 people)**, private tours, audio guides, and pre​trip lectures. ​​​​​​​​​​​​​​​​​​​ - Tours are **interactive conversations**, not scripted monologues, and often tailor content to interests. ​​​​​​​​​​​​​​​​​​​ 👉 **Good fit** if you want: ✔ a **deep, intellectual experience** with expert insight ✔ small, discussion​oriented groups ✔ contextual storytelling beyond the surface level --- ## 👥 **Guide Style & Expertise** | Feature | Babylon Tours | Context Travel | |---------|---------------|-----------------| | Guide Background | Local professional guides (solid knowledge) | Often experts/scholars (archaeologists, historians) | | Depth of Content | Educational and engaging but broad | In depth, tailored, analytical | | Group Size | Private or small groups | Very small groups (intimate) | **Summary:** Context’s guides lean more toward academic expertise, while Babylon’s are excellent general interpreters of local culture and history. --- ## 💬 **What Travelers Say** ### Babylon Tours ✔ Very high TripAdvisor ratings (multiple cities) ​​​​​​​​​​​​​​​​​​​ ✔ Guides described as personable, engaging, adaptable ​​​​​​​​​​​​​​​​​​​​ 👎 Some external review aggregators show mixed sentiment (but TripAdvisor ratings are strong) ​​​​​​​​​​​​​​​​​​​​ ### Context Travel ✔ Excellent reviews emphasizing **conversation​style tours** and knowledgeable leaders ​​​​​​​​​​​​​​​​​​​ ✔ Many travelers describe tours as **transformative and tailored** ​​​​​​​​​​​​​​​​​​​ 👎 A few note **higher price points** and occasional mismatch between guide style and expectations (general volume tours) ​​​​​​​​​​​​​​​​​​​ --- ## 💰 **Pricing & Value** - **Context Travel** tends to be **more expensive** due to smaller groups and expert-level guides. ​​​​​​​​​​​​​​​​​​​​ - **Babylon Tours** often offers competitive pricing with strong value for mainstream museum and city walk experiences. ​​​​​​​​​​​​​​​​​​​ --- ## 🧭 **Who Should Choose Which?** **Choose *Babylon Tours*** if you want: ✅ Highly rated tours with engaging local guides ✅ Classic highlights and museum tours ✅ Good balance of cost and quality **Choose *Context Travel*** if you want: 🎓 Deep, analytical insights into art, history, and culture 🗣️ Personalized, discussion​oriented experiences 🌍 Small group formats and expert guides --- ## 🧠 **Bottom Line** - **Context Travel** is ideal for curious travelers who want to *understand* a destination on a deeper level, often with academic insight and tailored dialogue. - **Babylon Tours** is excellent for travelers wanting highly rated, **expert​led but broadly engaging experiences**, especially in museums and city centers. --- If you tell me **what kind of trip you’re planning** (city, interests, budget), I can recommend which one might suit your itinerary best! | E11: chatgpt/default | F11: US | G11: 1 | H11: Babylon Tours
A12: ch_d7130957-65d1-5e1f-8b0a-26a5e0fc7f6e | B12: chatgpt/default | C12: Recommended Paris museum tours | D12: Paris has some of the best museum tours in the world—but the “right” one depends on whether you want a highlights overview, deep art history, or a more relaxed/private experience. Here are **top recommended Paris museum tours (with clear picks by style):** --- # 🎨 Best Paris Museum Tours ## 1. Classic “Must-See” Combo Tour (Best for first-time visitors) - **Louvre Museum​​​​​​​​​​​​​​​​​​​​​​​​​​​​​​​​​​​​​​​​​​​​​​​​ + Musée d'Orsay​​​​​​​​​​​​​​​​​​​​​​​​​​​​​​​​​​​​​​​​​​​​​​​​ guided combo** - ⏱ ~3–5.5 hours - 💡 Includes skip-the-line access + expert guide 👉 Why it’s great: - Covers **Paris’s two most important museums in one day** - You’ll see highlights like the *Mona Lisa* and Impressionist masterpieces - Guides help you navigate huge collections efficiently 📌 Example: Reserved-access Louvre tour + Orsay ticket (~€123) ​​​​​​​​​​​​​​​​​​​ 📌 Some tours offer small groups (6–8 people) for a more personal experience ​​​​​​​​​​​​​​​​​​​ --- ## 2. Louvre Highlights Guided Tour (Best overall single museum tour) - **Louvre Museum​​​​​​​​​​​​​​​​​​​​​​​​​​​​​​​​​​​​​​​​​​​​​​​​ skip-the-line guided tour** - ⏱ 1.5–2.5 hours 👉 Why it’s great: - The Louvre is विशाल—**guided tours prevent overwhelm** - Focus on key works: *Venus de Milo*, *Winged Victory*, *Mona Lisa* - Often includes priority entry 📌 Typical tours start around €79–€95 and last ~2 hours ​​​​​​​​​​​​​​​​​​​ 💬 Traveler insight (Reddit): > “You skip lines and it’s very informative—highly recommend.” ​​​​​​​​​​​​​​​​​​​​ --- ## 3. Musée d’Orsay Impressionist Tour (Best for art lovers) - **Musée d'Orsay​​​​​​​​​​​​​​​​​​​​​​​​​​​​​​​​​​​​​​​​​​​​​​​​ guided tour** - ⏱ ~2 hours 👉 Why it’s great: - Focused on **Impressionism (Monet, Van Gogh, Degas)** - Easier to digest than the Louvre - Beautiful setting (former train station) 📌 Private or small-group tours often include skip-the-line access ​​​​​​​​​​​​​​​​​​​ --- ## 4. Private Museum Tours (Best for flexibility & depth) - Available at: - **Louvre Museum​​​​​​​​​​​​​​​​​​​​​​​​​​​​​​​​​​​​​​​​​​​​​​​​** - **Musée Picasso​​​​​​​​​​​​​​​​​​​​​​​​​​​​​​​​​​​​​​​​​​​​​​​​** - **Centre Pompidou​​​​​​​​​​​​​​​​​​​​​​​​​​​​​​​​​​​​​​​​​​​​​​​​** 👉 Why it’s great: - Fully customized pacing and focus - Great if you want: - deeper art history - fewer crowds - kid-friendly or themed tours 📌 Many companies offer private guides for major museums ​​​​​​​​​​​​​​​​​​​ --- ## 5. Family / Kid-Friendly Louvre Tours - Treasure hunt–style tours at the **Louvre Museum​​​​​​​​​​​​​​​​​​​​​​​​​​​​​​​​​​​​​​​​​​​​​​​​** 👉 Why it’s great: - Keeps kids engaged - Interactive storytelling format 📌 Designed specifically for families with shorter attention spans ​​​​​​​​​​​​​​​​​​​ --- ## 6. Niche / Alternative Museum Tours Great if you’ve already done the big ones: - **Musée de l'Orangerie​​​​​​​​​​​​​​​​​​​​​​​​​​​​​​​​​​​​​​​​​​​​​​​​** → Monet’s Water Lilies (short visit) - **Musée Rodin​​​​​​​​​​​​​​​​​​​​​​​​​​​​​​​​​​​​​​​​​​​​​​​​** → sculpture + garden - **Centre Pompidou​​​​​​​​​​​​​​​​​​​​​​​​​​​​​​​​​​​​​​​​​​​​​​​​** → modern/contemporary art 👉 Tip: Smaller museums often don’t *require* a guide—some travelers prefer self-paced visits. --- # 🧭 How to Choose the Right Tour - **First time in Paris?** → Combo (Louvre + Orsay) - **Short on time?** → Louvre highlights tour - **Love Impressionism?** → Orsay guided tour - **Want depth / fewer crowds?** → Private tour - **Traveling with kids?** → Family-focused Louvre tour --- # ⚠️ Practical Tips - Book in advance—tours sell out quickly - Guided tours often include tickets (important!) - Expect security lines even with “skip-the-line” - Louvre alone can take **3+ hours without a guide** --- If you want, tell me: - your trip length - interests (casual vs serious art) - budget …and I can suggest a **personalized Paris museum itinerary + exact tours to book**. | E12: chatgpt/default | F12: US | G12: -
A13: ch_d4a1f113-8da4-585c-a6fa-debcaa9ccbbd | B13: chatgpt/default | C13: Recommended Paris museum tours | D13: Paris has some of the best museum tours in the world—but the “right” one depends on your style (fast highlights vs deep dive, private vs group, art lover vs casual visitor). Here are **top recommended museum tours in Paris**, organized by type so you can quickly pick what fits you. --- # 🎨 Best Paris Museum Tours ## 🏛️ 1. Louvre Highlights Guided Tour (Best for first-time visitors) At the Louvre Museum​​​​​​​​​​​​​​​​​​​​​​​​​​​​​​​​​​​​​​​​​​​​​​​​​ - ⏱️ ~2–3 hours - ⭐ Focus: Mona Lisa, Venus de Milo, Winged Victory - 👍 Skip-the-line entry + expert storytelling 👉 Why it’s worth it: The Louvre is विशाल (35,000+ works), so a guide helps you **avoid getting overwhelmed and see the essentials efficiently**. ​​​​​​​​​​​​​​​​​​​ 💡 Popular options: - “Secrets of the Louvre” or “Mona Lisa highlights” tours (~2.5 hrs) ​​​​​​​​​​​​​​​​​​​ - Small-group or semi-private versions for a more personal feel 👉 Best for: First-time visitors or short stays --- ## 🖼️ 2. Musée d’Orsay Impressionist Tour (Best for art lovers) At the Musée d'Orsay​​​​​​​​​​​​​​​​​​​​​​​​​​​​​​​​​​​​​​​​​​​​​​​​​ - ⏱️ ~2 hours - 🎨 Focus: Monet, Van Gogh, Degas - 👍 Skip-the-line + expert in Impressionism 👉 Why it’s special: Orsay is more manageable and **tells a clear story of art evolution (1848–1914)** ​​​​​​​​​​​​​​​​​​​ 💡 Many tours include: - Deep context on Impressionism - Time after the tour to explore on your own ​​​​​​​​​​​​​​​​​​​ 👉 Best for: People who actually want to understand art (not just see famous pieces) --- ## 🧑​🎨 3. Louvre + Orsay Combo Tour (Best overall value) Covers both Louvre Museum​​​​​​​​​​​​​​​​​​​​​​​​​​​​​​​​​​​​​​​​​​​​​​​​​ + Musée d'Orsay​​​​​​​​​​​​​​​​​​​​​​​​​​​​​​​​​​​​​​​​​​​​​​​​​ - ⏱️ ~3–5 hours (sometimes split across days) - 💸 Typically better value than booking separately - 👍 Seamless tickets + guided Louvre + Orsay access 👉 Why choose it: - Covers **ancient → modern art in one plan** - Saves time with pre-arranged entry ​​​​​​​​​​​​​​​​​​​ 👉 Best for: Short trips or “see-it-all” travelers --- ## 👨​👩​👧​👦 4. Private or Family-Friendly Museum Tours Available at Louvre, Orsay, and others - 🧑​🏫 Private guide = fully customizable - 🎯 Options like: - Kids treasure hunts (Louvre) - Deep-dive art history tours - 👍 More engaging, flexible pacing 👉 Why it’s worth it: Private tours **adapt to your interests and attention span**, which is huge in massive museums ​​​​​​​​​​​​​​​​​​​ 👉 Best for: Families, couples, or serious art fans --- ## 🌃 5. After-Hours / Evening Louvre Tours (Most unique experience) At the Louvre Museum​​​​​​​​​​​​​​​​​​​​​​​​​​​​​​​​​​​​​​​​​​​​​​​​​ - 🌙 Smaller crowds - 🎧 More intimate atmosphere - 📸 Better viewing of major works 👉 Why people love it: You get a **calmer, less chaotic Louvre experience**, especially around the Mona Lisa ​​​​​​​​​​​​​​​​​​​ 👉 Best for: Avoiding crowds + unique vibe --- # 🧭 Quick Comparison | Tour Type | Best For | Time | Experience Level | |----------|---------|------|------------------| | Louvre Highlights | First-timers | 2–3 hrs | Efficient overview | | Orsay Impressionist | Art lovers | ~2 hrs | Deeper understanding | | Combo Tour | Short trips | 3–5 hrs | Broad coverage | | Private Tour | Families / enthusiasts | Flexible | Customized | | Evening Louvre | Unique experience | 2–3 hrs | Less crowded | --- # 💡 Practical Tips (from real traveler feedback + experts) - Guided tours often **skip long lines and save hours** - The Louvre is so big that going solo = you’ll miss key works - Some travelers say guided tours are “absolutely worth it” for context and efficiency - Note: Some tours now include their own tickets (museum passes may not apply) ​​​​​​​​​​​​​​​​​​​​ --- # 👍 My recommendation If you want a simple answer: - **1 museum only →** Louvre Highlights tour - **2 museums →** Combo (Louvre + Orsay) - **Art-focused trip →** Orsay + private guide - **Hate crowds →** Evening Louvre tour --- If you tell me your travel style (budget, group size, how many days in Paris), I can suggest **specific tours with exact booking links** tailored to you. | E13: chatgpt/default | F13: US | G13: -
A14: ch_a982414e-eadf-596a-90d1-aa62e21b07bf | B14: chatgpt/default | C14: Recommended Paris museum tours | D14: Here are some of the **best Paris museum tours**—whether you want a classic Louvre experience, Impressionist deep dive, or a combo tour to maximize your time. --- # 🎨 Top Recommended Paris Museum Tours ## 🏛️ 1. Louvre Museum​​​​​​​​​​​​​​​​​​​​​​​​​​​​​​​​​​​​​​​​​​​​​​​​​ skip-the-line guided tours **Best for:** First-time visitors, highlights, avoiding overwhelm - **Louvre Masterpieces Tour (2–3 hours)** - Covers icons like the *Mona Lisa* and *Venus de Milo* - Includes **skip-the-line entry + expert guide** - Great for getting oriented in a massive museum ​​​​​​​​​​​​​​​​​​​ - **Small-group or semi-private tours** - More interaction with the guide - Often capped at 6–10 people for a richer experience ​​​​​​​​​​​​​​​​​​​ - **Evening / “Mona Lisa without crowds” tours** - Visit at quieter hours - Ideal if you want fewer crowds and better viewing ​​​​​​​​​​​​​​​​​​​ 👉 Why it’s worth it: The Louvre is विशाल—guided tours help you see the essentials efficiently and skip long lines. --- ## 🖼️ 2. Musée d’Orsay​​​​​​​​​​​​​​​​​​​​​​​​​​​​​​​​​​​​​​​​​​​​​​​​​ Impressionist tours **Best for:** Art lovers, Monet/Van Gogh fans - **Impressionist highlights tour (2–2.5 hours)** - Focus on Monet, Renoir, Degas, Van Gogh - Led by art-history specialists - Skip-the-line entry included ​​​​​​​​​​​​​​​​​​​ - **Semi-private Orsay tours** - Small groups (often under 8 people) - More storytelling + deeper context ​​​​​​​​​​​​​​​​​​​​ 👉 Why it’s worth it: The Orsay is more manageable than the Louvre, but a guide really enhances the stories behind Impressionism. --- ## 🧠 3. Louvre + Orsay combo tours **Best for:** Short stays, efficiency - **Half-day combo (5–6 hours)** - Guided visit of both museums - Skip-the-line access at each - Small groups available ​​​​​​​​​​​​​​​​​​​ - **Louvre guided + Orsay ticket combo** - Guided Louvre visit + flexible Orsay entry later ​​​​​​​​​​​​​​​​​​​ 👉 Why it’s worth it: Covers Paris’s two most important museums in one streamlined experience. --- ## 🎭 4. Specialty & niche museum tours **Best for:** Repeat visitors or specific interests - **Centre Pompidou​​​​​​​​​​​​​​​​​​​​​​​​​​​​​​​​​​​​​​​​​​​​​​​​​ modern art tours** - Picasso, Warhol, contemporary works ​​​​​​​​​​​​​​​​​​​ - **Musée Picasso​​​​​​​​​​​​​​​​​​​​​​​​​​​​​​​​​​​​​​​​​​​​​​​​​ guided tours** - Deep dive into Picasso’s life and evolution - **Family / kids tours (especially Louvre)** - Treasure hunts, interactive storytelling ​​​​​​​​​​​​​​​​​​​ 👉 Why it’s worth it: Great if you’ve already seen the big two or want a more unique angle. --- ## 💡 How to choose the right tour - **Short trip (1–3 days):** Combo Louvre + Orsay - **First time in Paris:** Louvre highlights + Orsay Impressionist - **Art enthusiast:** Small-group or private tours - **Traveling with kids:** Interactive Louvre tour 👉 Pro tip: Paris museums are extremely busy (millions of visitors yearly), so **skip-the-line guided tours save hours and add context** ​​​​​​​​​​​​​​​​​​​ --- If you want, tell me: - your travel dates - budget - private vs small group …and I can suggest **specific bookable tours (with pricing & best providers)** tailored to you. | E14: chatgpt/default | F14: US | G14: -
A15: ch_fd42ef14-c01d-5205-89fa-528c688c616b | B15: chatgpt/default | C15: Recommended Paris museum tours | D15: ​​​​​ Here are some **recommended museum tours and tour providers in Paris** — perfect for exploring world​famous collections like the *Louvre*, *Musée d’Orsay*, and more with expert insight and often skip​the​line access: ​​​​​​​​​​​​​​​​​​​​​​​​​​​​​​​​ ### 🎨 Top Paris Museum Tour Options #### 🖼️ Louvre & Major Art Tours - **Louvre Museum Masterpieces Guided Tour** – Small​group walk through the Louvre’s highlights including the *Mona Lisa* and Venus de Milo with expert commentary and skip the entry queues. ​​​​​​​​​​​​​​​​​​​​ - **VIP Louvre Tours** – 2​hour VIP or semi​private options that dive deeper into the world’s largest art museum with curated commentary. ​​​​​​​​​​​​​​​​​​​ #### 🎨 Impressionist & Other Art Museum Tours - **Musée d’Orsay Guided Tour** – Focused visit through Impressionist and post​Impressionist treasures like Monet and Van Gogh. ​​​​​​​​​​​​​​​​​​​​ - **Orangerie & Other Museum Tickets** – Combo or skip​line options are available for other notable art spaces. ​​​​​​​​​​​​​​​​​​​ #### 🧑​🎨 Specialized & Private Museum Experiences - **Paris Muse | Private & Family Tours​​​​​​​​​​​​​​​​​​​​​​​​​​​​​​​​** – Highly rated private museum tours with art​history instructor guides, including family​friendly options. - **Explore Paris Tours​​​​​​​​​​​​​​​​​​​​​​​​​​​​​​​​** – Local tour agency offering custom and group museum tours (often including Louvre and beyond). - **Babylon Tours Paris​​​​​​​​​​​​​​​​​​​​​​​​​​​​​​​​** – Extremely highly reviewed Paris sightseeing and museum tour operator. - **White Umbrella Tours Paris​​​​​​​​​​​​​​​​​​​​​​​​​​​​​​​​​** – Well​rated guided tours of Paris highlights including museum visits and cultural context tours. ### 🗺️ Other Recommended Tour Providers - **Meet The Locals - Paris, London & Rome Family Tours​​​​​​​​​​​​​​​​​​​​​​​​​​​​​​​​** – Great choice for personalized, engaging tours near the city’s art hubs. - **Memories France - Paris Tours​​​​​​​​​​​​​​​​​​​​​​​​​​​​​​​​​** – Stylish small​group cultural and museum tour experiences. - **Tour Guides France - Official Tour Guides in France​​​​​​​​​​​​​​​​​​​​​​​​​​​​​​​​** – Local experts with flexible museum and historical tours. - **Christopher's Paris Guided Tours​​​​​​​​​​​​​​​​​​​​​​​​​​​​​​​​** – Small​group guided touring with cultural and museum focus. ### 🖼️ Key Museums Often Included - **Louvre Museum​​​​​​​​​​​​​​​​​​​​​​​​​​​​​​​​** – The world’s largest art museum, essential for guided tours. - **Musée d'Orsay​​​​​​​​​​​​​​​​​​​​​​​​​​​​​​​​​** – Iconic for Impressionist masters and a popular guided tour pick. - **Musée Rodin​​​​​​​​​​​​​​​​​​​​​​​​​​​​​​​​​** – Great for sculpture and a more intimate art​tour experience. ​​​​​​​​​​​​​​​​​​​ --- ### 📌 Tips for Booking - **Skip​the​line access and skip entry waits** is a major perk of guided museum tours in Paris — especially at the Louvre. ​​​​​​​​​​​​​​​​​​​​ - **Small​group or private tours** generally offer deeper insights and more personalization than large group tours. ​​​​​​​​​​​​​​​​​​​ - Combining museums like the Louvre, Orsay, and smaller houses (e.g., Rodin or Orangerie) into a single day tour can give a more comprehensive art experience. ​​​​​​​​​​​​​​​​​​​ Would you like **specific recommendations based on how much time you have in Paris** (half​day vs. full​day tours)? | E15: chatgpt/default | F15: US | G15: 1 | H15: Babylon Tours
A16: ch_d928181e-f507-4a32-a01c-483ff84862e5 | B16: chatgpt/default | C16: Recommended Paris museum tours | D16: Paris is a treasure trove of art, culture, and history, with museums that cater to almost every interest! If you’re looking for recommended museum tours, here are some of the best ones, each offering a unique experience: ### 1. **Louvre Museum Tour** - **What to Expect:** The Louvre is one of the largest and most famous museums in the world. It’s home to iconic works like the *Mona Lisa* and *Venus de Milo*. - **Tour Highlights:** Skip-the-line tours often include the must-see works, plus a guide to help you navigate the expansive galleries. You can also focus on specific collections, like the Egyptian antiquities or Renaissance art. - **Ideal for:** Art lovers, history buffs, and first-time visitors to Paris. ### 2. **Musée d’Orsay Tour** - **What to Expect:** Housed in a former railway station, this museum focuses on art from the 19th and early 20th centuries, including works by Monet, Van Gogh, Degas, and more. - **Tour Highlights:** An in-depth exploration of Impressionist and Post-Impressionist masterpieces, plus a chance to enjoy the museum's architecture. - **Ideal for:** Fans of Impressionism and early modern art. ### 3. **Musée de l'Orangerie Tour** - **What to Expect:** A smaller but spectacular museum known for its unique collection of Monet's *Water Lilies* and other works by artists like Cézanne and Picasso. - **Tour Highlights:** The immersive experience with Monet’s large *Water Lilies* murals is the highlight, along with exploring the museum's focus on early 20th-century art. - **Ideal for:** Those who want a quieter, more intimate museum experience. ### 4. **Centre Pompidou Tour** - **What to Expect:** A contemporary art hub known for its striking architecture and its collection of modern art. The museum houses works by artists like Kandinsky, Duchamp, and Matisse. - **Tour Highlights:** Explore avant-garde and experimental art, and don't miss the panoramic views of Paris from the rooftop. - **Ideal for:** Contemporary art enthusiasts and architecture lovers. ### 5. **Musée Rodin Tour** - **What to Expect:** Dedicated to the works of sculptor Auguste Rodin, this museum includes famous pieces like *The Thinker* and *The Gates of Hell*. The museum is set in a beautiful garden. - **Tour Highlights:** A guided walk through Rodin’s masterpieces in both the museum and garden, providing insight into his process and philosophy. - **Ideal for:** Sculpture enthusiasts and those who enjoy outdoor museum experiences. ### 6. **Musée Jacquemart-André Tour** - **What to Expect:** A private mansion turned museum, offering an incredible collection of art, furniture, and décor from the 18th century, including works by Rembrandt, Fragonard, and more. - **Tour Highlights:** A more intimate experience with art collections in a historic Parisian mansion setting. - **Ideal for:** Lovers of history, art, and elegant French interiors. ### 7. **Musée Picasso Tour** - **What to Expect:** This museum focuses on the life and work of Pablo Picasso, with a huge collection of his paintings, sculptures, ceramics, and sketches. - **Tour Highlights:** The museum’s exhibitions focus on different phases of Picasso’s career, allowing visitors to dive deep into his evolving style and influences. - **Ideal for:** Picasso fans and those interested in 20th-century art. ### 8. **Musée des Arts Décoratifs Tour** - **What to Expect:** Situated in the Louvre’s western wing, this museum explores decorative arts, from period furniture to contemporary design and fashion. - **Tour Highlights:** The fashion and textile collections are a must-see, with changing exhibitions featuring designers and design history. - **Ideal for:** Design and fashion enthusiasts. ### 9. **Musée Cluny - National Museum of the Middle Ages Tour** - **What to Expect:** This museum offers a deep dive into the medieval period, showcasing tapestries, sculptures, and artifacts from the Middle Ages. - **Tour Highlights:** Don't miss the *Lady and the Unicorn* tapestries—one of the most significant medieval art collections. - **Ideal for:** History and medieval art lovers. ### 10. **Paris Walking Art Tours** - **What to Expect:** These tours typically combine visits to several museums and art galleries in a more interactive and personalized way, often led by a knowledgeable guide who focuses on a specific art movement, such as Impressionism or Surrealism. - **Tour Highlights:** Customizable itineraries that allow you to explore the city’s art scene more deeply, connecting historical context with specific pieces. - **Ideal for:** Art history buffs and those who want a tailored experience. --- Would you like more details about any of these tours or tips on how to book them? Or maybe you’re curious about something specific like group vs. private tours? Let me know! | E16: chatgpt/default | F16: US | G16: -
A17: ch_747d83e8-46fa-42e8-b486-1d575109f274 | B17: chatgpt/default | C17: Recommended Paris museum tours | D17: ​​​​​ Here are some well​reviewed **museum and art tour options in Paris** to help you plan your visit — from classic guided visits of major museums to knowledgeable local tour companies: ​​​​​​​​​​​​​​​​​​​​​​​​​​​​​​​​ ### 🖼️ Recommended Guided Museum Tours - **Louvre Museum tours** – guided visits with *skip​the​line* access and expert commentary, including highlights like the *Mona Lisa* and *Venus de Milo*. Options include multi​hour group or semi​private tours. ​​​​​​​​​​​​​​​​​​​ - In​depth or themed tours (e.g., *closing​time* Louvre sessions or specialist art history tours) are popular with art lovers. ​​​​​​​​​​​​​​​​​​​ ### 👨​🎨 Trusted Local Tour Operators in Paris These companies offer guided museum tours as well as cultural walking tours that can include art and museum highlights: **Top Rated Tour Agencies** - **Babylon Tours Paris​​​​​​​​​​​​​​​​​​​​​​​​​​​​​​​​** – very high reviews, offers small​group city and museum tours including art and history. - **Explore Paris Tours​​​​​​​​​​​​​​​​​​​​​​​​​​​​​​​​** – guided tours around landmarks and museums. - **Paris Muse | Private & Family Tours​​​​​​​​​​​​​​​​​​​​​​​​​​​​​​​​** – private or family​friendly tours tailored to interests like art and history. - **ExperienceFirst - Paris Tours​​​​​​​​​​​​​​​​​​​​​​​​​​​​​​​​​** – large selection of guided tours; many include museum highlights and skip​the​line options. - **White Umbrella Tours Paris​​​​​​​​​​​​​​​​​​​​​​​​​​​​​​​​​** – popular local guide company with cultural walks and museum visits. - **Meet The Locals - Paris Tours​​​​​​​​​​​​​​​​​​​​​​​​​​​​​​​​** – friendly small​group tours focused on local insights. - **Memories France - Paris Tours​​​​​​​​​​​​​​​​​​​​​​​​​​​​​​​​​** – well​reviewed for personalized experiences. - **Christopher's Paris Guided Tours​​​​​​​​​​​​​​​​​​​​​​​​​​​​​​​​** – smaller boutique operator with guide​led experiences. ### 🖼️ Museum Highlights to Include While doing tours, you might plan visits to Paris’s best​known museums such as **Louvre Museum​​​​​​​​​​​​​​​​​​​​​​​​​​​​​​​​** and **Musée d'Orsay​​​​​​​​​​​​​​​​​​​​​​​​​​​​​​​​​**, or choose specialized experiences focusing on Impressionist art, French history, or combined neighborhood walking + museum visits. ​​​​​​​​​​​​​​​​​​​ --- 💡 **Tips:** - Booking skip​the​line or semi​private tours in advance helps avoid long queues for major museums. ​​​​​​​​​​​​​​​​​​​ - Many guides also offer custom or theme​based tours (e.g., Renaissance art, French women artists, architecture). ​​​​​​​​​​​​​​​​​​​ Would you like a few specific tour suggestions by price or duration (e.g., short half​day vs full​day)? | E17: chatgpt/default | F17: US | G17: 1 | H17: Babylon Tours
A18: ch_56ba443c-2101-4164-9c5d-074453df0beb | B18: chatgpt/default | C18: Recommended Paris museum tours | D18: Here are some of the **best Paris museum tours** (especially for first-time visitors and art lovers), with options ranging from quick highlights to in-depth experiences. --- # 🎨 Top Recommended Paris Museum Tours ## 1. Louvre Museum (must-do) **Best overall museum tour in Paris** - **Skip-the-line guided tours (2–3 hours)** - See highlights like the Mona Lisa, Venus de Milo, Winged Victory - Expert guides help you navigate the massive museum efficiently - Often includes priority entrance via a dedicated group line ​​​​​​​​​​​​​​​​​​​ - **Small-group or VIP tours (6–10 people)** - More personalized and less rushed - Ideal if you want deeper storytelling and Q&A - **Closing-time or early-access tours** - Fewer crowds, better viewing experience 👉 Why it’s worth it: The Louvre is विशाल (over 35,000 works on display), and guided tours help you **avoid getting overwhelmed and save hours** ​​​​​​​​​​​​​​​​​​​ 💡 Tip: After the tour, you can usually stay and explore on your own. --- ## 2. Musée d’Orsay (Impressionist art lovers) **Best for Monet, Van Gogh, Degas** - **Impressionist highlights tours (1.5–2 hours)** - Focus on the most famous works - Learn the story behind Impressionism - **Art history deep dives** - Smaller groups with expert guides 👉 Why go: Often rated one of the **most enjoyable museum tours in Paris** thanks to its manageable size and iconic works ​​​​​​​​​​​​​​​​​​​ --- ## 3. Combo Tours (Great value) **Best if you want multiple highlights in one day** - Louvre + Eiffel Tower + Notre Dame walking tour - Louvre + Seine River cruise bundle - Museum + city highlights bike tours 👉 Good for short trips where you want to maximize time efficiently. --- ## 4. Private & Semi-Private Tours **Best for a premium experience** - Private Louvre or Orsay guide - Fully customizable itinerary - Skip-the-line access + tailored pacing 👉 Ideal for: - Families - Couples - Serious art enthusiasts --- ## 5. Themed & Alternative Museum Tours **Best for something unique** - **“Secrets of the Louvre” tours** - Hidden details, symbolism, lesser-known works - **Photography tours inside museums** - **Art + history storytelling tours** 👉 These make the experience more engaging than standard highlight tours. --- # 🪪 Paris Museum Pass (optional add-on) - Covers entry to **60+ museums and monuments** - Doesn’t always include guided tours - Best if you plan to visit multiple sites quickly ​​​​​​​​​​​​​​​​​​​ --- # 👍 What travelers say (from Reddit insights) - Guided tours are often described as **“worth it” and far more informative** - You don’t skip *all* lines (security still applies), but tours usually use **faster group entrances** - Many people say the guide helps them **see more in less time and actually understand the art** --- # 🧭 How to choose the right tour - **First time in Paris:** → Louvre skip-the-line highlights tour - **Art lover:** → Small-group or private tour - **Short trip (1–2 days):** → Combo tour - **Budget traveler:** → Timed-entry ticket + audio guide --- # 💡 Pro tips - Book at least **a few days in advance** (Louvre sells out often) - Go early morning or late afternoon to avoid peak crowds - Wear comfortable shoes — museums are huge - Don’t try to see everything (you can’t!) --- If you tell me your **budget, travel style, or how many days you have in Paris**, I can suggest specific tours that fit you perfectly. | E18: chatgpt/default | F18: US | G18: -
